<mujoco model="thormang_v5">
    <compiler angle="radian" />
    <size njmax="500" nconmax="100" />
	
	<default>
	
	<joint damping="5"/>
	<geom rgba = ".7 .7 .7 1"/>
	<default class="viz">
			<geom contype="0" conaffinity="0" group="1" type="mesh" rgba=".6 .6 .7 1"/>
	</default>
	
	</default>
	
	
	<option timestep='0.002'/>
	
    <asset>
        <mesh name="Pelvis" file="Pelvis.STL" />
        <mesh name="R0" file="R0.STL" />
        <mesh name="R1" file="R1.STL" />
        <mesh name="R2" file="R2.STL" />
        <mesh name="R3" file="R3.STL" />
        <mesh name="R4" file="R4.STL" />
        <mesh name="R5" file="R5.STL" />
        <mesh name="L0" file="L0.STL" />
        <mesh name="L1" file="L1.STL" />
        <mesh name="L2" file="L2.STL" />
        <mesh name="L3" file="L3.STL" />
        <mesh name="L4" file="L4.STL" />
        <mesh name="L5" file="L5.STL" />
        <mesh name="Waist" file="Waist.STL" />
        <mesh name="Body" file="Body.STL" />
        <mesh name="UR0" file="UR0.STL" />
        <mesh name="UR1" file="UR1.STL" />
        <mesh name="UR2" file="UR2.STL" />
        <mesh name="UR3" file="UR3.STL" />
        <mesh name="UR4" file="UR4.STL" />
        <mesh name="UR5" file="UR5.STL" />
        <mesh name="UR6" file="UR6.STL" />
        <mesh name="UL0" file="UL0.STL" />
        <mesh name="UL1" file="UL1.STL" />
        <mesh name="UL2" file="UL2.STL" />
        <mesh name="UL3" file="UL3.STL" />
        <mesh name="UL4" file="UL4.STL" />
        <mesh name="UL5" file="UL5.STL" />
        <mesh name="UL6" file="UL6.STL" />
    </asset>
    <worldbody>
		<geom name="ground" type="plane" pos="0 0 0" size="4 4 .05" friction="1 0.005 0.0001" rgba="0.7 0.6 0.5 1"/>
		<geom name="box" type="box" size="0.5 0.5 2" pos="1.2 0 0"/>
		<light mode='targetbodycom' target='Pelvis' directional='false' diffuse='.8 .8 .8' specular='0.3 0.3 0.3' pos='0 0 4.0' dir='0 0 -1'/>
		
		
		
	
	
        <body name="Pelvis" pos="0 0 0.89">
			<joint type="free" limited='false' damping="0" stiffness="0" armature="0"/>
            <inertial pos="-0.00105981 0 0.0819865" quat="0.707107 0.707107 -5.18248e-05 5.18248e-05" mass="1.99939" diaginertia="0.013505 0.0115794 0.0035553" />
            <geom type="box" size="0.04 0.14 0.06" pos="0 0 0.085"/>
			<geom class="viz" mesh="Pelvis" />
            <body name="R0" pos="0 -0.105 0">
                <inertial pos="-0.0308912 0 -0.0343573" quat="0.648531 0.281794 0.281794 0.648531" mass="1.49504" diaginertia="0.00586649 0.00407585 0.00252357" />
                <joint name="JR0" pos="0 0 0" axis="0 0 1" />
                <geom type="box" size="0.071 0.031 0.08" pos="-0.025 0 -0.06" />
				<geom class="viz" mesh="R0" />
                <body name="R1" pos="-0.0175 0 -0.1024">
                    <inertial pos="0.0116 0.0106426 0.000331808" quat="0.500823 0.499176 -0.499176 0.500823" mass="1.02296" diaginertia="0.00172337 0.00167402 0.000626618" />
                    <joint name="JR1" pos="0 0 0" axis="1 0 0" />
                    <geom class="viz" mesh="R1" />
                    <body name="R2" pos="0.0116 0.01075 0">
                        <inertial pos="0.126227 0.00125 -0.241194" quat="0.975245 0 -0.221125 0" mass="3.2021" diaginertia="0.0376779 0.0340782 0.0100414" />
                        <joint name="JR2" pos="0 0 0" axis="0 1 0" />
						<geom type="box" size="0.04 0.06 0.15" pos="0.15 0 -0.22"/>
						<geom type="box" size="0.04 0.06 0.07" pos="0.075 0 -0.14"/>
                        <geom class="viz" mesh="R2" />
                        <body name="R3" pos="0.1515 0 -0.339">
                            <inertial pos="-0.0703253 0.0159776 -0.236061" quat="0.970118 0.0693967 0.232366 -0.00786095" mass="2.02413" diaginertia="0.0271609 0.0240284 0.00461135" />
                            <joint name="JR3" pos="0 0 0" axis="0 1 0" />
							<geom type="box" size="0.04 0.06 0.15 " pos=" -0.07 0.01 -0.22" quat="0.9659         0    0.2588         0"/>
                            <geom class="viz" mesh="R3" />
                            <body name="R4" pos="-0.132038 -0.00485 -0.348697">
                                <inertial pos="-0.0105201 0 0" quat="0 0.707107 0 0.707107" mass="1.03487" diaginertia="0.00172847 0.00168805 0.000637306" />
                                <joint name="JR4" pos="0 0 0" axis="0 1 0" />
                                <geom class="viz" mesh="R4" />
                                <body name="R5" pos="0 0 0">
                                    <inertial pos="-0.00139937 0 -0.0862969" quat="0 0.710071 0 0.70413" mass="1.29698" diaginertia="0.0107556 0.00846043 0.00294499" />
                                    <joint name="JR5" pos="0 0 0" axis="1 0 0" />
									<geom type="box" size="0.15 0.085 0.01" friction="1.5 0.005 0.0001" pos="0 0 -0.09"/>
                                    <geom class="viz" mesh="R5" />
                                </body>
                            </body>
                        </body>
                    </body>
                </body>
            </body>
            <body name="L0" pos="0 0.105 0">
                <inertial pos="-0.0308912 0 -0.0343573" quat="0.648531 0.281794 0.281794 0.648531" mass="1.49504" diaginertia="0.00586649 0.00407585 0.00252357" />
                <joint name="JL0" pos="0 0 0" axis="0 0 1" />
                <geom type="box" size="0.071 0.031 0.08" pos="-0.025 0 -0.06" />
				<geom class="viz" mesh="L0" />
                <body name="L1" pos="-0.0175 0 -0.1024">
                    <inertial pos="0.0116 -0.0106426 0.000331808" quat="0.499176 0.500823 -0.500823 0.499176" mass="1.02296" diaginertia="0.00172337 0.00167402 0.000626618" />
                    <joint name="JL1" pos="0 0 0" axis="1 0 0" />
                    <geom class="viz" mesh="L1" />
                    <body name="L2" pos="0.0116 -0.01075 0">
                        <inertial pos="0.126227 -0.00125 -0.241194" quat="0.975245 0 -0.221125 0" mass="3.2021" diaginertia="0.0376779 0.0340782 0.0100414" />
                        <joint name="JL2" pos="0 0 0" axis="0 1 0" />
						<geom type="box" size="0.04 0.06 0.15" pos="0.15 0 -0.22"/>
						<geom type="box" size="0.04 0.06 0.07" pos="0.075 0 -0.14"/>
                        <geom class="viz" mesh="L2" />
                        <body name="L3" pos="0.1515 0 -0.339">
                            <inertial pos="-0.0703253 -0.0159776 -0.236061" quat="0.970118 -0.0693967 0.232366 0.00786095" mass="2.02413" diaginertia="0.0271609 0.0240284 0.00461135" />
                            <joint name="JL3" pos="0 0 0" axis="0 1 0" />
							<geom type="box" size="0.04 0.06 0.15 " pos=" -0.07 -0.01 -0.22" quat="0.9659         0    0.2588         0"/>
                            <geom class="viz" mesh="L3" />
                            <body name="L4" pos="-0.132038 0.00485 -0.348697">
                                <inertial pos="-0.0105201 0 0" quat="0 0.707107 0 0.707107" mass="1.03487" diaginertia="0.00172847 0.00168805 0.000637306" />
                                <joint name="JL4" pos="0 0 0" axis="0 1 0" />
                                <geom class="viz" mesh="L4" />
                                <body name="L5" pos="0 0 0">
                                    <inertial pos="-0.00139937 0 -0.0862969" quat="0 0.710071 0 0.70413" mass="1.29698" diaginertia="0.0107556 0.00846043 0.00294499" />
                                    <joint name="JL5" pos="0 0 0" axis="1 0 0" />
									<geom type="box" size="0.15 0.085 0.01" friction="1.5 0.005 0.0001" pos="0 0 -0.09"/>
                                    <geom class="viz" mesh="L5" />
                                </body>
                            </body>
                        </body>
                    </body>
                </body>
            </body>
            <body name="Waist" pos="0 0 0">
                <inertial pos="0 0 0.17827" quat="0.5 0.5 0.5 0.5" mass="0.176842" diaginertia="0.000457259 0.000457225 8.63489e-05" />
                <joint name="JW" pos="0 0 0" axis="0 0 1" />
                <geom class="viz" mesh="Waist" />
                <body name="Body" pos="0 0 0.2185">
                    <inertial pos="-7.87563e-06 0 0.120999" quat="0.499435 0.499435 -0.500564 0.500564" mass="10.7799" diaginertia="0.109346 0.104941 0.0846794" />
                    <joint name="JB" pos="0 0 0" axis="1 0 0" />
					<geom type="box" size="0.12 0.14 0.105" pos="0 0 0.125"/>
					<geom type="box" size="0.09 0.05 0.05" pos="0 0 0"/>
                    <geom class="viz" mesh="Body" />
					
					
					<body name="Head" pos="0 0 0.33">
						<inertial pos="0 0 0" mass="0" diaginertia="0 0 0"/>
						<geom type="box" size="0.07 0.05 0.06" pos="0 0 0.005"/>
						<geom type="box" size="0.07 0.01 0.02" pos="-0.06 0.06 0.07" quat="0.9659         0    0.2588         0"/>
						<geom type="box" size="0.07 0.01 0.02" pos="-0.06 -0.06 0.07" quat="0.9659         0    0.2588         0"/>
						<geom type="box" size="0.005 0.015 0.005" pos="0.07 0.03 0.03" rgba="0 0 0 1"/>
						<geom type="box" size="0.005 0.015 0.005" pos="0.07 -0.03 0.03" rgba="0 0 0 1"/>
					</body>
					
					
                    <body name="UR0" pos="0 -0.17 0.239">
                        <inertial pos="0.00028444 0.00120963 -0.000698379" quat="0.183009 0.683014 0.183016 0.683012" mass="0.92826" diaginertia="0.00155774 0.0015422 0.000471396" />
                        <joint name="JUR0" pos="0 0 0" axis="0 0.866025 -0.5" />
                        <geom class="viz" mesh="UR0" />
                        <body name="UR1" pos="0 0 0">
                            <inertial pos="0 -0.0335621 -0.030402" quat="0.505827 0.494104 0.505827 0.494104" mass="0.373609" diaginertia="0.00149395 0.001164 0.000654385" />
                            <joint name="JUR1" pos="0 0 0" axis="1 0 0" />
                            <geom class="viz" mesh="UR1" />
                            <body name="UR2" pos="0 -0.0288557 0">
                                <inertial pos="-0.000466491 0 -0.214087" quat="0.707102 0.00259455 0.00259455 0.707102" mass="1.75122" diaginertia="0.0105713 0.0101552 0.00125893" />
                                <joint name="JUR2" pos="0 0 0" axis="0 0 1" />
								<geom type="box" size="0.03 0.03 0.1" pos="0 0 -0.17"/>
								<geom type="box" size="0.059 0.03 0.03" pos="0 0 -0.295"/>
                                <geom class="viz" mesh="UR2" />
                                <body name="UR3" pos="0 0 -0.294">
                                    <inertial pos="-0.000131563 -0.0706245 -0.0270194" quat="0.700806 -0.069744 0.0711015 0.706365" mass="0.833431" diaginertia="0.00120842 0.00115447 0.000701231" />
                                    <joint name="JUR3" pos="0 0 0" axis="1 0 0" />
									<geom type="box" size="0.03 0.03 0.05" pos="0 -0.075 -0.025"/>
                                    <geom class="viz" mesh="UR3" />
                                    <body name="UR4" pos="-0.00015 -0.075 -0.0235">
                                        <inertial pos="-0.000378331 0 -0.190037" quat="0.707102 0.00262861 0.00262861 0.707102" mass="0.523867" diaginertia="0.00287737 0.00280073 0.000269159" />
                                        <joint name="JUR4" pos="0 0 0" axis="0 0 1" />
										<geom type="box" size="0.03 0.028 0.12" pos="0 0 -.18"/>
                                        <geom class="viz" mesh="UR4" />
                                        <body name="UR5" pos="0 0 -0.285">
                                            <inertial pos="0 0 -0.029698" quat="0.5 0.5 0.5 0.5" mass="0.0695" diaginertia="9.1278e-05 9.0005e-05 2.1312e-05" />
                                            <joint name="JUR5" pos="0 0 0" axis="1 0 0" />
                                            <geom class="viz" mesh="UR5" />
                                            <body name="UR6" pos="0 0 -0.033">
                                                <inertial pos="0 -0.0031654 -0.16931" quat="0.707079 -0.00629289 0.00629289 0.707079" mass="1.206" diaginertia="0.00640781 0.0045882 0.00258779" />
                                                <joint name="JUR6" pos="0 0 0" axis="0 0 1" />
												<geom type="box" size="0.1 .04 0.05" pos="0 0 -0.2"/>
                                                <geom class="viz" mesh="UR6" />
                                            </body>
                                        </body>
                                    </body>
                                </body>
                            </body>
                        </body>
                    </body>
                    <body name="UL0" pos="0 0.17 0.239">
                        <inertial pos="0.00028444 -0.00120963 -0.000698379" quat="-0.183009 0.683014 -0.183016 0.683012" mass="0.92826" diaginertia="0.00155774 0.0015422 0.000471396" />
                        <joint name="JUL0" pos="0 0 0" axis="0 0.866025 0.5" />
                        <geom class="viz" mesh="UL0" />
                        <body name="UL1" pos="0 0 0">
                            <inertial pos="0 0.0335621 -0.030402" quat="0.494104 0.505827 0.494104 0.505827" mass="0.373609" diaginertia="0.00149395 0.001164 0.000654385" />
                            <joint name="JUL1" pos="0 0 0" axis="1 0 0" />
                            <geom class="viz" mesh="UL1" />
                            <body name="UL2" pos="0 0.0288557 0">
                                <inertial pos="-0.000466491 0 -0.214087" quat="0.707102 0.00259455 0.00259455 0.707102" mass="1.75122" diaginertia="0.0105713 0.0101552 0.00125893" />
                                <joint name="JUL2" pos="0 0 0" axis="0 0 1" />
								<geom type="box" size="0.03 0.03 0.1" pos="0 0 -0.17"/>
								<geom type="box" size="0.059 0.03 0.03" pos="0 0 -0.295"/>
                                <geom class="viz" mesh="UL2" />
                                <body name="UL3" pos="0 0 -0.294">
                                    <inertial pos="-0.000131563 0.0706245 -0.0270194" quat="0.706365 0.0711015 -0.069744 0.700806" mass="0.833431" diaginertia="0.00120842 0.00115447 0.000701231" />
                                    <joint name="JUL3" pos="0 0 0" axis="1 0 0" />
									<geom type="box" size="0.03 0.03 0.05" pos="0 0.075 -0.025"/>
                                    <geom class="viz" mesh="UL3" />
                                    <body name="UL4" pos="-0.00015 0.075 -0.0235">
                                        <inertial pos="-0.000378331 0 -0.190037" quat="0.707102 0.00262861 0.00262861 0.707102" mass="0.523867" diaginertia="0.00287737 0.00280073 0.000269159" />
                                        <joint name="JUL4" pos="0 0 0" axis="0 0 1" />
										<geom type="box" size="0.03 0.028 0.12" pos="0 0 -.18"/>
                                        <geom class="viz" mesh="UL4" />
                                        <body name="UL5" pos="0 0 -0.285">
                                            <inertial pos="0 0 -0.029698" quat="0.5 0.5 0.5 0.5" mass="0.0695" diaginertia="9.1278e-05 9.0005e-05 2.1312e-05" />
                                            <joint name="JUL5" pos="0 0 0" axis="1 0 0" />
                                            <geom class="viz" mesh="UL5" />
                                            <body name="UL6" pos="0 0 -0.033">
                                                <inertial pos="0 0.0031654 -0.16931" quat="0.707079 0.00629289 -0.00629289 0.707079" mass="1.206" diaginertia="0.00640781 0.0045882 0.00258779" />
                                                <joint name="JUL6" pos="0 0 0" axis="0 0 1" />
												<geom type="box" size="0.1 .04 0.05" pos="0 0 -0.2"/>
                                                <geom class="viz" mesh="UL6" />
                                            </body>
                                        </body>
                                    </body>
                                </body>
                            </body>
                        </body>
                    </body>
                </body>
            </body>
        </body>
    </worldbody>
	
	<actuator>		
		<motor name="MR0" joint="JR0"/>
		<motor name="MR1" joint="JR1"/>
		<motor name="MR2" joint="JR2"/>
		<motor name="MR3" joint="JR3"/>
		<motor name="MR4" joint="JR4"/>
		<motor name="MR5" joint="JR5"/>
		
		<motor name="ML0" joint="JL0"/>
		<motor name="ML1" joint="JL1"/>
		<motor name="ML2" joint="JL2"/>
		<motor name="ML3" joint="JL3"/>
		<motor name="ML4" joint="JL4"/>
		<motor name="ML5" joint="JL5"/>
		
		<motor name="MW" joint="JW"/>
		<motor name="MB" joint="JB"/>
		
		<motor name="MUR0" joint="JUR0"/>
		<motor name="MUR1" joint="JUR1"/>
		<motor name="MUR2" joint="JUR2"/>
		<motor name="MUR3" joint="JUR3"/>
		<motor name="MUR4" joint="JUR4"/>
		<motor name="MUR5" joint="JUR5"/>
		<motor name="MUR6" joint="JUR6"/>
		
		<motor name="MUL0" joint="JUL0"/>
		<motor name="MUL1" joint="JUL1"/>
		<motor name="MUL2" joint="JUL2"/>
		<motor name="MUL3" joint="JUL3"/>
		<motor name="MUL4" joint="JUL4"/>
		<motor name="MUL5" joint="JUL5"/>
		<motor name="MUL6" joint="JUL6"/>
		
		
	</actuator>
	
	
	
</mujoco>
