<?xml version="1.0" ?>
<robot
  name="red_robot">
<mujoco>
	<compiler meshdir="../meshes/" balanceinertia="true"/>
</mujoco>
  <link
    name="Pelvis_link">
    <inertial>
      <origin
        xyz="-0.0099622 6.3628E-07 0.012618"
        rpy="0 0 0" />
      <mass
        value="0.90054" />
      <inertia
        ixx="0.0094751"
        ixy="9.2894E-09"
        ixz="-9.4052E-06"
        iyy="0.0022311"
        iyz="-9.4189E-06"
        izz="0.010198" />
    </inertial>
    <visual>
      <origin
        xyz="0 0 0"
        rpy="0 0 0" />
      <geometry>
        <mesh
          filename="package://red_description/meshes/test/Pelvis_link.STL" />
      </geometry>
      <material
        name="">
        <color
          rgba="0.20313 0.20313 0.20313 1" />
      </material>
    </visual>
    <collision>
      <origin
        xyz="0 0 0"
        rpy="0 0 0" />
      <geometry>
        <mesh
          filename="package://red_description/meshes/test/Pelvis_link.STL" />
      </geometry>
    </collision>
  </link>
  <link
    name="HipRoll_R_link">
    <inertial>
      <origin
        xyz="-0.06477 0 0.05149"
        rpy="0 0 0" />
      <mass
        value="2.679" />
      <inertia
        ixx="0.01821"
        ixy="-1.676E-07"
        ixz="-0.0007745"
        iyy="0.03121"
        iyz="-4.53E-09"
        izz="0.2928" />
    </inertial>
    <visual>
      <origin
        xyz="0 0 0"
        rpy="0 0 0" />
      <geometry>
        <mesh
          filename="package://red_description/meshes/test/HipRoll_R_link.STL" />
      </geometry>
      <material
        name="">
        <color
          rgba="0.20313 0.20313 0.20313 1" />
      </material>
    </visual>
  </link>
  <joint
    name="HipRoll_R_Joint"
    type="revolute">
    <origin
      xyz="0 -0.1025 -0.1225"
      rpy="0 0 0" />
    <parent
      link="Pelvis_link" />
    <child
      link="HipRoll_R_link" />
    <axis
      xyz="0 0 1" />
    <limit effort="25.42" lower="-0.2618" upper="0.2618" velocity="1.045"/>
    <dynamics
      damping="10" />
  </joint>
  <link
    name="HipCenter_R_Link">
    <inertial>
      <origin
        xyz="-0.04801 -0.0022 2E-05"
        rpy="0 0 0" />
      <mass
        value="2.67" />
      <inertia
        ixx="0.3553"
        ixy="1.725E-08"
        ixz="-3.236E-06"
        iyy="0.009161"
        iyz="-4.778E-06"
        izz="0.00876" />
    </inertial>
    <visual>
      <origin
        xyz="0 0 0"
        rpy="0 0 0" />
      <geometry>
        <mesh
          filename="package://red_description/meshes/test/HipCenter_R_Link.STL" />
      </geometry>
      <material
        name="">
        <color
          rgba="0.20313 0.20313 0.20313 1" />
      </material>
    </visual>
  </link>
  <joint
    name="HipCenter_R_Joint"
    type="revolute">
    <origin
      xyz="0 0 0"
      rpy="0 0 0" />
    <parent
      link="HipRoll_R_link" />
    <child
      link="HipCenter_R_Link" />
    <axis
      xyz="1 0 0" />
    <limit effort="46.6" lower="-0.5236" upper="0.2618" velocity="2.09"/>
    <dynamics
      damping="10" />
  </joint>
  <link
    name="Thigh_R_Link">
    <inertial>
      <origin
        xyz="-0.00042 -0.00032 -0.18904"
        rpy="0 0 0" />
      <mass
        value="5.366" />
      <inertia
        ixx="0.2987"
        ixy="-4.284E-05"
        ixz="-0.000196"
        iyy="0.7088"
        iyz="0.002406"
        izz="0.00982" />
    </inertial>
    <visual>
      <origin
        xyz="0 0 0"
        rpy="0 0 0" />
      <geometry>
        <mesh
          filename="package://red_description/meshes/test/Thigh_R_Link.STL" />
      </geometry>
      <material
        name="">
        <color
          rgba="0.85938 0.07813 0.23438 1" />
      </material>
    </visual>
  </link>
  <joint
    name="Thigh_R_Joint"
    type="revolute">
    <origin
      xyz="0 0 0"
      rpy="0 0 0" />
    <parent
      link="HipCenter_R_Link" />
    <child
      link="Thigh_R_Link" />
    <axis
      xyz="0 1 0" />
    <limit effort="46.6" lower="-1.6581" upper="0.4014" velocity="2.09"/>
    <dynamics
      damping="10" />
  </joint>
  <link
    name="Knee_R_Link">
    <inertial>
      <origin
        xyz="0.00429 0.00214 -0.1428"
        rpy="0 0 0" />
      <mass
        value="3.883" />
      <inertia
        ixx="0.1506"
        ixy="-2.887E-05"
        ixz="-0.002607"
        iyy="0.5588"
        iyz="-0.001486"
        izz="0.007451" />
    </inertial>
    <visual>
      <origin
        xyz="0 0 0"
        rpy="0 0 0" />
      <geometry>
        <mesh
          filename="package://red_description/meshes/test/Knee_R_Link.STL" />
      </geometry>
      <material
        name="">
        <color
          rgba="0.85938 0.07813 0.23438 1" />
      </material>
    </visual>
  </link>
  <joint
    name="Knee_R_Joint"
    type="revolute">
    <origin
      xyz="0 0 -0.35"
      rpy="0 0 0" />
    <parent
      link="Thigh_R_Link" />
    <child
      link="Knee_R_Link" />
    <axis
      xyz="0 1 0" />
    <limit effort="38.17" lower="-0.0218" upper="1.9722" velocity="6.0"/>
    <dynamics
      damping="10" />
  </joint>
  <link
    name="AnkleCenter_R_Link">
    <inertial>
      <origin
        xyz="-0.00419 -0.0018 -0.0003"
        rpy="0 0 0" />
      <mass
        value="2.51" />
      <inertia
        ixx="0.002857"
        ixy="-1.422E-07"
        ixz="2.222E-06"
        iyy="0.4135"
        iyz="4.611E-06"
        izz="0.003345" />
    </inertial>
    <visual>
      <origin
        xyz="0 0 0"
        rpy="0 0 0" />
      <geometry>
        <mesh
          filename="package://red_description/meshes/test/AnkleCenter_R_Link.STL" />
      </geometry>
      <material
        name="">
        <color
          rgba="0.20313 0.20313 0.20313 1" />
      </material>
    </visual>
  </link>
  <joint
    name="AnkleCenter_R_Joint"
    type="revolute">
    <origin
      xyz="0 0 -0.35"
      rpy="0 0 0" />
    <parent
      link="Knee_R_Link" />
    <child
      link="AnkleCenter_R_Link" />
    <axis
      xyz="0 1 0" />
    <limit effort="25.76" lower="-1.5149" upper="1.7505" velocity="2.1"/>
    <dynamics
      damping="10" />
  </joint>
  <link
    name="AnkleRoll_R_Link">
    <inertial>
      <origin
        xyz="-0.00802 0 -0.08535"
        rpy="0 0 0" />
      <mass
        value="3.464" />
      <inertia
        ixx="0.1466"
        ixy="1.434E-05"
        ixz="-0.004731"
        iyy="0.05808"
        iyz="-2.508E-05"
        izz="0.0238" />
    </inertial>
    <visual>
      <origin
        xyz="0 0 0"
        rpy="0 0 0" />
      <geometry>
        <mesh
          filename="package://red_description/meshes/test/AnkleRoll_R_Link.STL" />
      </geometry>
      <material
        name="">
        <color
          rgba="0.85938 0.07813 0.23438 1" />
      </material>
    </visual>
    <collision>
      <origin
        xyz="0 0 0"
        rpy="0 0 0" />
      <geometry>
        <mesh filename="package://red_description/meshes/test/AnkleRoll_R_Link.STL" scale="1 1 1"/>
      </geometry>
    </collision>
  </link>
  <joint
    name="AnkleRoll_R_Joint"
    type="revolute">
    <origin
      xyz="0 0 0"
      rpy="0 0 0" />
    <parent
      link="AnkleCenter_R_Link" />
    <child
      link="AnkleRoll_R_Link" />
    <axis
      xyz="1 0 0" />
    <limit effort="25.76" lower="-0.3491" upper="0.3491" velocity="2.1"/>
    <dynamics
      damping="10" />
  </joint>
  <joint name="RLeg_effector_fixedjoint" type="fixed">
    <parent link="AnkleRoll_R_Link"/>
    <child link="r_sole"/>
    <origin rpy="0 0 0" xyz="0 0 -0.1451"/>
    <axis xyz="0 0 0"/>
  </joint>
  <link name="r_sole"/>
  <link
    name="HipRoll_L_Link">
    <inertial>
      <origin
        xyz="-0.06477 0 0.05149"
        rpy="0 0 0" />
      <mass
        value="2.679" />
      <inertia
        ixx="0.01821"
        ixy="-1.676E-07"
        ixz="-0.0007745"
        iyy="0.03121"
        iyz="-4.53E-09"
        izz="0.2928" />
    </inertial>
    <visual>
      <origin
        xyz="0 0 0"
        rpy="0 0 0" />
      <geometry>
        <mesh
          filename="package://red_description/meshes/test/HipRoll_L_Link.STL" />
      </geometry>
      <material
        name="">
        <color
          rgba="0.20313 0.20313 0.20313 1" />
      </material>
    </visual>
  </link>
  <joint
    name="HipRoll_L_Joint"
    type="revolute">
    <origin
      xyz="0 0.1025 -0.1225"
      rpy="0 0 0" />
    <parent
      link="Pelvis_link" />
    <child
      link="HipRoll_L_Link" />
    <axis
      xyz="0 0 1" />
    <limit effort="25.42" lower="-0.2618" upper="0.2618" velocity="1.045"/>
    <dynamics
      damping="10" />
  </joint>
  <link
    name="HipCenter_L_Link">
    <inertial>
      <origin
        xyz="-0.04801 0.0022 2E-05"
        rpy="0 0 0" />
      <mass
        value="2.67" />
      <inertia
        ixx="0.3553"
        ixy="1.725E-08"
        ixz="-3.236E-06"
        iyy="0.009161"
        iyz="-4.778E-06"
        izz="0.00876" />
    </inertial>
    <visual>
      <origin
        xyz="0 0 0"
        rpy="0 0 0" />
      <geometry>
        <mesh
          filename="package://red_description/meshes/test/HipCenter_L_Link.STL" />
      </geometry>
      <material
        name="">
        <color
          rgba="0.20313 0.20313 0.20313 1" />
      </material>
    </visual>
  </link>
  <joint
    name="HipCenter_L_Joint"
    type="revolute">
    <origin
      xyz="0 0 0"
      rpy="0 0 0" />
    <parent
      link="HipRoll_L_Link" />
    <child
      link="HipCenter_L_Link" />
    <axis
      xyz="1 0 0" />
    <limit effort="46.6" lower="-0.2618" upper="0.5236" velocity="2.09"/>
    <dynamics
      damping="10" />
  </joint>
  <link
    name="Thigh_L_Link">
    <inertial>
      <origin
        xyz="-0.00042 0.00032 -0.18904"
        rpy="0 0 0" />
      <mass
        value="5.366" />
      <inertia
        ixx="0.2987"
        ixy="-4.284E-05"
        ixz="-0.000196"
        iyy="0.7088"
        iyz="0.002406"
        izz="0.00982" />
    </inertial>
    <visual>
      <origin
        xyz="0 0 0"
        rpy="0 0 0" />
      <geometry>
        <mesh
          filename="package://red_description/meshes/test/Thigh_L_Link.STL" />
      </geometry>
      <material
        name="">
        <color
          rgba="0.85938 0.07813 0.23438 1" />
      </material>
    </visual>

  </link>
  <joint
    name="Thigh_L_Joint"
    type="revolute">
    <origin
      xyz="0 0 0"
      rpy="0 0 0" />
    <parent
      link="HipCenter_L_Link" />
    <child
      link="Thigh_L_Link" />
    <axis
      xyz="0 1 0" />
    <limit effort="46.6" lower="-1.6581" upper="0.4014" velocity="2.09"/>
    <dynamics
      damping="10" />
  </joint>
  <link
    name="Knee_L_Link">
    <inertial>
      <origin
        xyz="0.00429 -0.00214 -0.1428"
        rpy="0 0 0" />
      <mass
        value="3.883" />
      <inertia
        ixx="0.1506"
        ixy="-2.887E-05"
        ixz="-0.002607"
        iyy="0.5588"
        iyz="-0.001486"
        izz="0.007451" />
    </inertial>
    <visual>
      <origin
        xyz="0 0 0"
        rpy="0 0 0" />
      <geometry>
        <mesh
          filename="package://red_description/meshes/test/Knee_L_Link.STL" />
      </geometry>
      <material
        name="">
        <color
          rgba="0.85938 0.07813 0.23438 1" />
      </material>
    </visual>
    <collision>
      <origin
        xyz="0 0 0"
        rpy="0 0 0" />
      <geometry>
        <mesh
          filename="package://red_description/meshes/test/Knee_L_Link.STL" />
      </geometry>
    </collision>
  </link>
  <joint
    name="Knee_L_Joint"
    type="revolute">
    <origin
      xyz="0 0 -0.35"
      rpy="0 0 0" />
    <parent
      link="Thigh_L_Link" />
    <child
      link="Knee_L_Link" />
    <axis
      xyz="0 1 0" />
    <limit effort="38.17" lower="-0.0218" upper="1.9722" velocity="6.0"/>
    <dynamics
      damping="10" />
  </joint>
  <link
    name="AnkleCenter_L_Link">
    <inertial>
      <origin
        xyz="-0.00419 0.0018 -0.0003"
        rpy="0 0 0" />
      <mass
        value="2.51" />
      <inertia
        ixx="0.002857"
        ixy="-1.422E-07"
        ixz="2.222E-06"
        iyy="0.4135"
        iyz="4.611E-06"
        izz="0.003345" />
    </inertial>
    <visual>
      <origin
        xyz="0 0 0"
        rpy="0 0 0" />
      <geometry>
        <mesh
          filename="package://red_description/meshes/test/AnkleCenter_L_Link.STL" />
      </geometry>
      <material
        name="">
        <color
          rgba="0.20313 0.20313 0.20313 1" />
      </material>
    </visual>
    <collision>
      <origin
        xyz="0 0 0"
        rpy="0 0 0" />
      <geometry>
        <mesh
          filename="package://red_description/meshes/test/AnkleCenter_L_Link.STL" />
      </geometry>
    </collision>
  </link>
  <joint
    name="AnkleCenter_L_Joint"
    type="revolute">
    <origin
      xyz="0 0 -0.35"
      rpy="0 0 0" />
    <parent
      link="Knee_L_Link" />
    <child
      link="AnkleCenter_L_Link" />
    <axis
      xyz="0 1 0" />
    <limit effort="25.76" lower="-1.5149" upper="1.7505" velocity="2.1"/>
    <dynamics
      damping="10" />
  </joint>
  <link
    name="AnkleRoll_L_Link">
    <inertial>
      <origin
        xyz="-0.00802 0 -0.08535"
        rpy="0 0 0" />
      <mass
        value="3.464" />
      <inertia
        ixx="0.1466"
        ixy="1.434E-05"
        ixz="-0.004731"
        iyy="0.05808"
        iyz="-2.508E-05"
        izz="0.0238" />
    </inertial>
    <visual>
      <origin
        xyz="0 0 0"
        rpy="0 0 0" />
      <geometry>
        <mesh
          filename="package://red_description/meshes/test/AnkleRoll_L_Link.STL" />
      </geometry>
      <material
        name="">
        <color
          rgba="0.85938 0.07813 0.23438 1" />
      </material>
    </visual>
    <collision>
      <origin
        xyz="0 0 0"
        rpy="0 0 0" />
      <geometry>
        <mesh filename="package://red_description/meshes/test/AnkleRoll_L_Link.STL"/>
      </geometry>
    </collision>
  </link>
  <joint
    name="AnkleRoll_L_Joint"
    type="revolute">
    <origin
      xyz="0 0 0"
      rpy="0 0 0" />
    <parent
      link="AnkleCenter_L_Link" />
    <child
      link="AnkleRoll_L_Link" />
    <axis
      xyz="1 0 0" />
    <limit effort="25.76" lower="-0.3491" upper="0.3491" velocity="2.1"/>
    <dynamics
      damping="10" />
  </joint>
  <joint name="LLeg_effector_fixedjoint" type="fixed">
    <parent link="AnkleRoll_L_Link"/>
    <child link="l_sole"/>
    <origin rpy="0 0 0" xyz="0 0 -0.1451"/>
    <axis xyz="0 0 0"/>
  </joint>
  <link name="l_sole"/>
  <link
    name="Waist1">
    <inertial>
      <origin
        xyz="-0.00001 0.00756 -0.04182"
        rpy="0 0 0" />
      <mass
        value="0.74235" />
      <inertia
        ixx="0.003254680"
        ixy="-0.000000329"
        ixz="-0.000000257"
        iyy="0.001655456"
        iyz="0.000234637"
        izz="0.002701880" />
    </inertial>
    <visual>
      <origin
        xyz="0 0 0"
        rpy="0 0 0" />
      <geometry>
        <mesh
          filename="package://red_description/meshes/test/waist1.STL" />
      </geometry>
      <material
        name="">
        <color
          rgba="0.85938 0.07813 0.23438 1" />
      </material>
    </visual>
    <collision>
      <origin
        xyz="0 0 0"
        rpy="0 0 0" />
      <geometry>
        <mesh
          filename="package://red_description/meshes/test/waist1.STL" />
      </geometry>
    </collision>
  </link>
  <joint
    name="J_waist1"
    type="revolute">
    <origin
      xyz="0 0 0.18"
      rpy="0 0 0" />
    <parent
      link="Pelvis_link" />
    <child
      link="Waist1" />
    <axis
      xyz="0 0 1" />
    <limit
      lower="-2.094"
      upper="2.094"
      effort="300"
      velocity="10" />
   </joint>
   <link
    name="Waist2">
    <inertial>
      <origin
        xyz="-0.00065 0.00063 0.00001"
        rpy="0 0 0" />
      <mass
        value="3.27104" />
      <inertia
        ixx="0.004622862"
        ixy="-0.000031682"
        ixz="0.000000327"
        iyy="0.004974601"
        iyz="0.000002500"
        izz="0.006022159" />
    </inertial>
    <visual>
      <origin
        xyz="0 0 0"
        rpy="0 0 0" />
      <geometry>
        <mesh
          filename="package://red_description/meshes/test/waist2.STL" />
      </geometry>
      <material
        name="">
        <color
          rgba="0.20313 0.20313 0.20313 1" />
      </material>
    </visual>
    <collision>
      <origin
        xyz="0 0 0"
        rpy="0 0 0" />
      <geometry>
        <mesh
          filename="package://red_description/meshes/test/waist2.STL" />
      </geometry>
    </collision>
  </link>
  <joint
    name="J_waist2"
    type="revolute">
    <origin
      xyz="0 0 0"
      rpy="0 0 0" />
    <parent
      link="Waist1" />
    <child
      link="Waist2" />
    <axis
      xyz="0 1 0" />
    <limit
      lower="-2.094"
      upper="2.094"
      effort="300"
      velocity="10" />
  </joint>
<link
    name="Upperbody">
    <inertial>
      <origin
        xyz="-0.04733 0.00045 0.16266"
        rpy="0 0 0" />
      <mass
        value="16.43395" />
      <inertia
        ixx="0.267654041"
        ixy="0.002760359"
        ixz="0.024637907"
        iyy="0.242243423"
        iyz="-0.001029048"
        izz="0.179727804" />
    </inertial>
    <visual>
      <origin
        xyz="0 0 0"
        rpy="0 0 0" />
      <geometry>
        <mesh
          filename="package://red_description/meshes/test/upperbody.STL" />
      </geometry>
      <material
        name="">
        <color
          rgba="0.85938 0.07813 0.23438 1" />
      </material>
    </visual>
    <collision>
      <origin
        xyz="0 0 0"
        rpy="0 0 0" />
      <geometry>
        <mesh
          filename="package://red_description/meshes/test/upperbody.STL" />
      </geometry>
    </collision>
  </link>
  <joint
    name="J_waist3"
    type="revolute">
    <origin
      xyz="0 0 0"
      rpy="0 0 0" />
    <parent
      link="Waist2" />
    <child
      link="Upperbody" />
    <axis
      xyz="-1 0 0" />
    <limit
      lower="-2.094"
      upper="2.094"
      effort="300"
      velocity="10" />
  </joint>
  <link
    name="R_shoulder1">
    <inertial>
      <origin
        xyz="-0.00003 -0.00397 0.06029"
        rpy="0 0 0" />
      <mass
        value="1.6761" />
      <inertia
        ixx="0.001926270"
        ixy="0.000001508"
        ixz="-0.000003670"
        iyy="0.001936480"
        iyz="-0.000079164"
        izz="0.001677429" />
    </inertial>
    <visual>
      <origin
        xyz="0 0 0"
        rpy="0 0 0" />
      <geometry>
        <mesh
          filename="package://red_description/meshes/test/R_shoulder1.STL" />
      </geometry>
      <material
        name="">
        <color
          rgba="0.85938 0.07813 0.23438 1" />
      </material>
    </visual>
    <collision>
      <origin
        xyz="0 0 0"
        rpy="0 0 0" />
      <geometry>
        <mesh
          filename="package://red_description/meshes/test/R_shoulder1.STL" />
      </geometry>
    </collision>
  </link>
  <joint
    name="J_rshoulder1"
    type="revolute">
    <origin
      xyz="0.023 -0.154 0.2275"
      rpy="0 0 0" />
    <parent
      link="Upperbody" />
    <child
      link="R_shoulder1" />
    <axis
      xyz="0 0 1" />
    <limit
      lower="-1.54"
      upper="2.09"
      effort="70"
      velocity="10" />
  </joint>
  <link
    name="R_shoulder2">
    <inertial>
      <origin
        xyz="0.00107 -0.0491 -0.00001"
        rpy="0 0 0" />
      <mass
        value="0.4016" />
      <inertia
        ixx="0.000989903"
        ixy="-0.000028237"
        ixz="-0.000000465"
        iyy="0.000624253"
        iyz="-0.000000133"
        izz="0.001067575" />
    </inertial>
    <visual>
      <origin
        xyz="0 0 0"
        rpy="0 0 0" />
      <geometry>
        <mesh
          filename="package://red_description/meshes/test/R_shoulder2.STL" />
      </geometry>
      <material
        name="">
        <color
          rgba="0.20313 0.20313 0.20313 1" />
      </material>
    </visual>
    <collision>
      <origin
        xyz="0 0 0"
        rpy="0 0 0" />
      <geometry>
        <mesh
          filename="package://red_description/meshes/test/R_shoulder2.STL" />
      </geometry>
    </collision>
  </link>
  <joint
    name="J_rshoulder2"
    type="revolute">
    <origin
      xyz="0 -0.0341 0.065"
      rpy="0 0 0" />
    <parent
      link="R_shoulder1" />
    <child
      link="R_shoulder2" />
    <axis
      xyz="0 -1 0" />
    <limit
      lower="-3.14159"
      upper="3.14159"
      effort="70"
      velocity="10" />
  </joint>
  <link
    name="R_shoulder3">
    <inertial>
      <origin
        xyz="0.00262 -0.04826 0.00023"
        rpy="0 0 0" />
      <mass
        value="2.90141" />
      <inertia
        ixx="0.008441507"
        ixy="0.000365085"
        ixz="-0.000003267"
        iyy="0.002493763"
        iyz="0.000023746"
        izz="0.008296802" />
    </inertial>
    <visual>
      <origin
        xyz="0 0 0"
        rpy="0 0 0" />
      <geometry>
        <mesh
          filename="package://red_description/meshes/test/R_shoulder3.STL" />
      </geometry>
      <material
        name="">
        <color
          rgba="0.20313 0.20313 0.20313 1" />
      </material>
    </visual>
    <collision>
      <origin
        xyz="0 0 0"
        rpy="0 0 0" />
      <geometry>
        <mesh
          filename="package://red_description/meshes/test/R_shoulder3.STL" />
      </geometry>
    </collision>
  </link>
  <joint
    name="J_rshoulder3"
    type="revolute">
    <origin
      xyz="0 -0.115 0"
      rpy="0 0 0" />
    <parent
      link="R_shoulder2" />
    <child
      link="R_shoulder3" />
    <axis
      xyz="-1 0 0" />
    <limit
      lower="-1.9199"
      upper="1.9199"
      effort="70"
      velocity="10" />
  </joint>
  <link
    name="R_armlink">
    <inertial>
      <origin
        xyz="0.01896 -0.11642 -0.0119"
        rpy="0 0 0" />
      <mass
        value="0.43517" />
      <inertia
        ixx="0.002878609"
        ixy="-0.000302586"
        ixz="-0.000036001"
        iyy="0.000730323"
        iyz="-0.000398377"
        izz="0.003117058" />
    </inertial>
    <visual>
      <origin
        xyz="0 0 0"
        rpy="0 0 0" />
      <geometry>
        <mesh
          filename="package://red_description/meshes/test/R_arm.STL" />
      </geometry>
      <material
        name="">
        <color
          rgba="0.85938 0.07813 0.23438 1" />
      </material>
    </visual>
    <collision>
      <origin
        xyz="0 0 0"
        rpy="0 0 0" />
      <geometry>
        <mesh
          filename="package://red_description/meshes/test/R_arm.STL" />
      </geometry>
    </collision>
  </link>
  <joint
    name="J_rarm"
    type="revolute">
    <origin
      xyz="0 -0.1281 0"
      rpy="0 0 0" />
    <parent
      link="R_shoulder3" />
    <child
      link="R_armlink" />
    <axis
      xyz="0 -1 0" />
    <limit
      lower="-3.14159"
      upper="3.14159"
      effort="70"
      velocity="10" />
  </joint>
  <link
    name="R_elbow">
    <inertial>
      <origin
        xyz="-0.00136 -0.05256 0.01764"
        rpy="0 0 0" />
      <mass
        value="1.96511" />
      <inertia
        ixx="0.006375466"
        ixy="-0.000151764"
        ixz="0.000055158"
        iyy="0.001895543"
        iyz="-0.001530917"
        izz="0.005958821" />
    </inertial>
    <visual>
      <origin
        xyz="0 0 0"
        rpy="0 0 0" />
      <geometry>
        <mesh
          filename="package://red_description/meshes/test/R_elbow.STL" />
      </geometry>
      <material
        name="">
        <color
          rgba="0.20313 0.20313 0.20313 1" />
      </material>
    </visual>
    <collision>
      <origin
        xyz="0 0 0"
        rpy="0 0 0" />
      <geometry>
        <mesh
          filename="package://red_description/meshes/test/R_elbow.STL" />
      </geometry>
    </collision>
  </link>
  <joint
    name="J_relbow"
    type="revolute">
    <origin
      xyz="0 -0.207 -0.0325"
      rpy="0 0 0" />
    <parent
      link="R_armlink" />
    <child
      link="R_elbow" />
    <axis
      xyz="1 0 0" />
    <limit
      lower="-2.967"
      upper="3.14159"
      effort="40"
      velocity="10" />
  </joint>
  <link
    name="R_forearm">
    <inertial>
      <origin
        xyz="0.01426 -0.0767 0.00033"
        rpy="0 0 0" />
      <mass
        value="0.30234" />
      <inertia
        ixx="0.001053636"
        ixy="-0.000084568"
        ixz="0.000022117"
        iyy="0.000399479"
        iyz="-0.000019539"
        izz="0.001266418" />
    </inertial>
    <visual>
      <origin
        xyz="0 0 0"
        rpy="0 0 0" />
      <geometry>
        <mesh
          filename="package://red_description/meshes/test/R_forearm.STL" />
      </geometry>
      <material
        name="">
        <color
          rgba="0.85938 0.07813 0.23438 1" />
      </material>
    </visual>
    <collision>
      <origin
        xyz="0 0 0"
        rpy="0 0 0" />
      <geometry>
        <mesh
          filename="package://red_description/meshes/test/R_forearm.STL" />
      </geometry>
    </collision>
  </link>
  <joint
    name="J_rforearm"
    type="revolute">
    <origin
      xyz="0 -0.1244 0.0325"
      rpy="0 0 0" />
    <parent
      link="R_elbow" />
    <child
      link="R_forearm" />
    <axis
      xyz="0 -1 0" />
    <limit
      lower="-3.14159"
      upper="3.14159"
      effort="40"
      velocity="10" />
  </joint>
  <link
    name="R_wrist1">
    <inertial>
      <origin
        xyz="-0.00158 -0.02153 0.00003"
        rpy="0 0 0" />
      <mass
        value="0.70923" />
      <inertia
        ixx="0.000648197"
        ixy="-0.000024218"
        ixz="0.000000263"
        iyy="0.000396376"
        iyz="-0.000000688"
        izz="0.000683187" />
    </inertial>
    <visual>
      <origin
        xyz="0 0 0"
        rpy="0 0 0" />
      <geometry>
        <mesh
          filename="package://red_description/meshes/test/R_wrist1.STL" />
      </geometry>
      <material
        name="">
        <color
          rgba="0.20313 0.20313 0.20313 1" />
      </material>
    </visual>
    <collision>
      <origin
        xyz="0 0 0"
        rpy="0 0 0" />
      <geometry>
        <mesh
          filename="package://red_description/meshes/test/R_wrist1.STL" />
      </geometry>
    </collision>
  </link>
  <joint
    name="J_rwrist1"
    type="revolute">
    <origin
      xyz="0 -0.1451 0"
      rpy="0 0 0" />
    <parent
      link="R_forearm" />
    <child
      link="R_wrist1" />
    <axis
      xyz="1 0 0" />
    <limit
      lower="-3.14159"
      upper="3.14159"
      effort="10"
      velocity="10" />
  </joint>
  <link
    name="R_wrist2">
    <inertial>
      <origin
        xyz="0.00063 -0.04326 0.00178"
        rpy="0 0 0" />
      <mass
        value="2.0" />
      <inertia
        ixx="0.000865450"
        ixy="0.000080148"
        ixz="-0.000004217"
        iyy="0.000696917"
        iyz="0.000017697"
        izz="0.001520823" />
    </inertial>
    <visual>
      <origin
        xyz="0 -0.02 0"
        rpy="0 0 0" />
      <geometry>
        <mesh
          filename="package://red_description/meshes/test/R_wrist2.STL" />
      </geometry>
      <material
        name="">
        <color
          rgba="0.85938 0.07813 0.23438 1" />
      </material>
    </visual>
    <collision>
      <origin
        xyz="0 -0.02 0"
        rpy="0 0 0" />
      <geometry>
        <mesh
          filename="package://red_description/meshes/test/R_wrist2.STL" />
      </geometry>
    </collision>
  </link>
  <joint
    name="J_rwrist2"
    type="revolute">
    <origin
      xyz="0 -0.046 0"
      rpy="0 0 0" />
    <parent
      link="R_wrist1" />
    <child
      link="R_wrist2" />
    <axis
      xyz="0 0 1" />
    <limit
      lower="-2.094"
      upper="2.094"
      effort="10"
      velocity="10" />
  </joint>
  <link
    name="L_shoulder1">
    <inertial>
      <origin
        xyz="-0.00003 0.00397 0.06029"
        rpy="0 0 0" />
      <mass
        value="1.6762" />
      <inertia
        ixx="0.001925606"
        ixy="-0.000001433"
        ixz="-0.000002313"
        iyy="0.001936576"
        iyz="0.000078962"
        izz="0.001678498" />
    </inertial>
    <visual>
      <origin
        xyz="0 0 0"
        rpy="0 0 0" />
      <geometry>
        <mesh
          filename="package://red_description/meshes/test/L_shoulder1.STL" />
      </geometry>
      <material
        name="">
        <color
          rgba="0.85938 0.07813 0.23438 1" />
      </material>
    </visual>
    <collision>
      <origin
        xyz="0 0 0"
        rpy="0 0 0" />
      <geometry>
        <mesh
          filename="package://red_description/meshes/test/L_shoulder1.STL" />
      </geometry>
    </collision>
  </link>
  <joint
    name="J_lshoulder1"
    type="revolute">
    <origin
      xyz="0.023 0.154 0.2275"
      rpy="0 0 0" />
    <parent
      link="Upperbody" />
    <child
      link="L_shoulder1" />
    <axis
      xyz="0 0 1" />
    <limit
      lower="-2.09"
      upper="1.54"
      effort="70"
      velocity="10" />
  </joint>
  <link
    name="L_shoulder2">
    <inertial>
      <origin
        xyz="0.00105 0.0491 0.00072"
        rpy="0 0 0" />
      <mass
        value="0.4016" />
      <inertia
        ixx="0.000990650"
        ixy="0.000028629"
        ixz="0.000004859"
        iyy="0.000624637"
        iyz="0.000011123"
        izz="0.001067212" />
    </inertial>
    <visual>
      <origin
        xyz="0 0 0"
        rpy="0 0 0" />
      <geometry>
        <mesh
          filename="package://red_description/meshes/test/L_shoulder2.STL" />
      </geometry>
      <material
        name="">
        <color
          rgba="0.20313 0.20313 0.20313 1" />
      </material>
    </visual>
    <collision>
      <origin
        xyz="0 0 0"
        rpy="0 0 0" />
      <geometry>
        <mesh
          filename="package://red_description/meshes/test/L_shoulder2.STL" />
      </geometry>
    </collision>
  </link>
  <joint
    name="J_lshoulder2"
    type="revolute">
    <origin
      xyz="0 0.0341 0.065"
      rpy="0 0 0" />
    <parent
      link="L_shoulder1" />
    <child
      link="L_shoulder2" />
    <axis
      xyz="0 1 0" />
    <limit
      lower="-3.14159"
      upper="3.14159"
      effort="70"
      velocity="10" />
  </joint>
  <link
    name="L_shoulder3">
    <inertial>
      <origin
        xyz="0.00262 0.04826 0.00023"
        rpy="0 0 0" />
      <mass
        value="2.90141" />
      <inertia
        ixx="0.008441559"
        ixy="-0.000365084"
        ixz="-0.000002746"
        iyy="0.002493784"
        iyz="-0.000023821"
        izz="0.008296854" />
    </inertial>
    <visual>
      <origin
        xyz="0 0 0"
        rpy="0 0 0" />
      <geometry>
        <mesh
          filename="package://red_description/meshes/test/L_shoulder3.STL" />
      </geometry>
      <material
        name="">
        <color
          rgba="0.20313 0.20313 0.20313 1" />
      </material>
    </visual>
    <collision>
      <origin
        xyz="0 0 0"
        rpy="0 0 0" />
      <geometry>
        <mesh
          filename="package://red_description/meshes/test/L_shoulder3.STL" />
      </geometry>
    </collision>
  </link>
  <joint
    name="J_lshoulder3"
    type="revolute">
    <origin
      xyz="0 0.115 0"
      rpy="0 0 0" />
    <parent
      link="L_shoulder2" />
    <child
      link="L_shoulder3" />
    <axis
      xyz="-1 0 0" />
    <limit
      lower="-1.9199"
      upper="1.9199"
      effort="70"
      velocity="10" />
  </joint>
  <link
    name="L_armlink">
    <inertial>
      <origin
        xyz="0.01896 0.11642 -0.0119"
        rpy="0 0 0" />
      <mass
        value="0.43489" />
      <inertia
        ixx="0.002877598"
        ixy="0.000302757"
        ixz="-0.000036249"
        iyy="0.000779930"
        iyz="-0.000397833"
        izz="0.003115995" />
    </inertial>
    <visual>
      <origin
        xyz="0 0 0"
        rpy="0 0 0" />
      <geometry>
        <mesh
          filename="package://red_description/meshes/test/L_arm.STL" />
      </geometry>
      <material
        name="">
        <color
          rgba="0.85938 0.07813 0.23438 1" />
      </material>
    </visual>
    <collision>
      <origin
        xyz="0 0 0"
        rpy="0 0 0" />
      <geometry>
        <mesh
          filename="package://red_description/meshes/test/L_arm.STL" />
      </geometry>
    </collision>
  </link>
  <joint
    name="J_larm"
    type="revolute">
    <origin
      xyz="0 0.1281 0"
      rpy="0 0 0" />
    <parent
      link="L_shoulder3" />
    <child
      link="L_armlink" />
    <axis
      xyz="0 1 0" />
    <limit
      lower="-3.14159"
      upper="3.14159"
      effort="70"
      velocity="10" />
  </joint>
  <link
    name="L_elbow">
    <inertial>
      <origin
        xyz="-0.00136 0.05256 0.01764"
        rpy="0 0 0" />
      <mass
        value="1.96511" />
      <inertia
        ixx="0.006375466"
        ixy="0.000151764"
        ixz="0.000055158"
        iyy="0.001895543"
        iyz="0.001530917"
        izz="0.005958821" />
    </inertial>
    <visual>
      <origin
        xyz="0 0 0"
        rpy="0 0 0" />
      <geometry>
        <mesh
          filename="package://red_description/meshes/test/L_elbow.STL" />
      </geometry>
      <material
        name="">
        <color
          rgba="0.20313 0.20313 0.20313 1" />
      </material>
    </visual>
    <collision>
      <origin
        xyz="0 0 0"
        rpy="0 0 0" />
      <geometry>
        <mesh
          filename="package://red_description/meshes/test/L_elbow.STL" />
      </geometry>
    </collision>
  </link>
  <joint
    name="J_lelbow"
    type="revolute">
    <origin
      xyz="0 0.207 -0.0325"
      rpy="0 0 0" />
    <parent
      link="L_armlink" />
    <child
      link="L_elbow" />
    <axis
      xyz="1 0 0" />
    <limit
      lower="-3.14159"
      upper="2.8"
      effort="40"
      velocity="10" />
  </joint>
  <link
    name="L_forearm">
    <inertial>
      <origin
        xyz="0.01426 0.0767 0.00033"
        rpy="0 0 0" />
      <mass
        value="0.30234" />
      <inertia
        ixx="0.001053636"
        ixy="0.000084568"
        ixz="0.000022117"
        iyy="0.000399479"
        iyz="0.000019539"
        izz="0.001266418" />
    </inertial>
    <visual>
      <origin
        xyz="0 0 0"
        rpy="0 0 0" />
      <geometry>
        <mesh
          filename="package://red_description/meshes/test/L_forearm.STL" />
      </geometry>
      <material
        name="">
        <color
          rgba="0.85938 0.07813 0.23438 1" />
      </material>
    </visual>
    <collision>
      <origin
        xyz="0 0 0"
        rpy="0 0 0" />
      <geometry>
        <mesh
          filename="package://red_description/meshes/test/L_forearm.STL" />
      </geometry>
    </collision>
  </link>
  <joint
    name="J_lforearm"
    type="revolute">
    <origin
      xyz="0 0.1244 0.0325"
      rpy="0 0 0" />
    <parent
      link="L_elbow" />
    <child
      link="L_forearm" />
    <axis
      xyz="0 1 0" />
    <limit
      lower="-3.14159"
      upper="3.14159"
      effort="40"
      velocity="10" />
  </joint>
  <link
    name="L_wrist1">
    <inertial>
      <origin
        xyz="-0.00158 0.02153 0.00003"
        rpy="0 0 0" />
      <mass
        value="0.70923" />
      <inertia
        ixx="0.000648197"
        ixy="0.000024218"
        ixz="-0.000000263"
        iyy="0.000396376"
        iyz="0.000000688"
        izz="0.000683187" />
    </inertial>
    <visual>
      <origin
        xyz="0 0 0"
        rpy="0 0 0" />
      <geometry>
        <mesh
          filename="package://red_description/meshes/test/L_wrist1.STL" />
      </geometry>
      <material
        name="">
        <color
          rgba="0.20313 0.20313 0.20313 1" />
      </material>
    </visual>
    <collision>
      <origin
        xyz="0 0 0"
        rpy="0 0 0" />
      <geometry>
        <mesh
          filename="package://red_description/meshes/test/L_wrist1.STL" />
      </geometry>
    </collision>
  </link>
  <joint
    name="J_lwrist1"
    type="revolute">
    <origin
      xyz="0 0.1451 0"
      rpy="0 0 0" />
    <parent
      link="L_forearm" />
    <child
      link="L_wrist1" />
    <axis
      xyz="1 0 0" />
    <limit
      lower="-3.14159"
      upper="3.14159"
      effort="10"
      velocity="10" />
  </joint>
  <link
    name="L_wrist2">
    <inertial>
      <origin
        xyz="0.00063 0.04326 0.00178"
        rpy="0 0 0" />
      <mass
        value="2.0" />
      <inertia
        ixx="0.000865450"
        ixy="-0.000080148"
        ixz="-0.000004217"
        iyy="0.000696917"
        iyz="-0.000017697"
        izz="0.001520823" />
    </inertial>
    <visual>
      <origin
        xyz="0 0.02 0"
        rpy="0 0 0" />
      <geometry>
        <mesh
          filename="package://red_description/meshes/test/L_wrist2.STL" />
      </geometry>
      <material
        name="">
        <color
          rgba="0.85938 0.07813 0.23438 1" />
      </material>
    </visual>
    <collision>
      <origin
        xyz="0 0.02 0"
        rpy="0 0 0" />
      <geometry>
        <mesh
          filename="package://red_description/meshes/test/L_wrist2.STL" />
      </geometry>
    </collision>
  </link>
  <joint
    name="J_lwrist2"
    type="revolute">
    <origin
      xyz="0 0.046 0"
      rpy="0 0 0" />
    <parent
      link="L_wrist1" />
    <child
      link="L_wrist2" />
    <axis
      xyz="0 0 1" />
    <limit
      lower="-2.094"
      upper="2.094"
      effort="10"
      velocity="10" />
  </joint>
  <link
    name="Neck">
    <inertial>
      <origin
        xyz="0 -0.00247 0.02752"
        rpy="0 0 0" />
      <mass
        value="0.37746" />
      <inertia
        ixx="0.000226034"
        ixy="0.000000001"
        ixz="-0.000000048"
        iyy="0.000105591"
        iyz="-0.000000210"
        izz="0.000226142" />
    </inertial>
    <visual>
      <origin
        xyz="0 0 0"
        rpy="0 0 0" />
      <geometry>
        <mesh
          filename="package://red_description/meshes/test/neck.STL" />
      </geometry>
      <material
        name="">
        <color
          rgba="0.20313 0.20313 0.20313 1" />
      </material>
    </visual>
    <collision>
      <origin
        xyz="0 0 0"
        rpy="0 0 0" />
      <geometry>
        <mesh
          filename="package://red_description/meshes/test/neck.STL" />
      </geometry>
    </collision>
  </link>
  <joint
    name="J_neck"
    type="revolute">
    <origin
      xyz="-0.036 0 0.3795"
      rpy="0 0 0" />
    <parent
      link="Upperbody" />
    <child
      link="Neck" />
    <axis
      xyz="0 0 1" />
    <limit
      lower="-2.094"
      upper="2.094"
      effort="10"
      velocity="10" />
  </joint>
  <link
    name="Head">
    <inertial>
      <origin
        xyz="0.01311 0.00002 0.12168"
        rpy="0 0 0" />
      <mass
        value="2.712" />
      <inertia
        ixx="0.008489520"
        ixy="-0.000001032"
        ixz="-0.000950888"
        iyy="0.010703088"
        iyz="0.000004728"
        izz="0.007440684" />
    </inertial>
    <visual>
      <origin
        xyz="0 0 0"
        rpy="0 0 0" />
      <geometry>
        <mesh
          filename="package://red_description/meshes/test/head.STL" />
      </geometry>
      <material
        name="">
        <color
          rgba="0.85938 0.07813 0.23438 1" />
      </material>
    </visual>
    <collision>
      <origin
        xyz="0 0 0"
        rpy="0 0 0" />
      <geometry>
        <mesh
          filename="package://red_description/meshes/test/head.STL" />
      </geometry>
    </collision>
  </link>
  <joint
    name="J_head"
    type="revolute">
    <origin
      xyz="0 0 0.0275"
      rpy="0 0 0" />
    <parent
      link="Neck" />
    <child
      link="Head" />
    <axis
      xyz="0 1 0" />
    <limit
      lower="-2.094"
      upper="2.094"
      effort="10"
      velocity="10" />
  </joint>
  </robot>
